<?xml version="1.0" encoding="utf-8"?>
<!-- =================================================================================== -->
<!-- |    This document was autogenerated by xacro from mz25_arm.urdf.xacro            | -->
<!-- |    EDITING THIS FILE BY HAND IS NOT RECOMMENDED                                 | -->
<!-- =================================================================================== -->
<robot name="mz25">
  <!-- for simulation -->
  <!--  <xacro:include filename="$(find franka_description)/robots/panda.gazebo.xacro"/>-->
  <!--  <xacro:include filename="panda.transmission.xacro"/>-->
  <!-- end for simulation -->
  <!-- for simulation -->
  <!--    <link name="world" />-->
  <!--    <joint name="robot_to_world" type="fixed">-->
  <!--      <parent link="world" />-->
  <!--      <child link="${arm_id}_link0" />-->
  <!--      <origin xyz="0.0 0.0 0.0" rpy="0.0 0.0 0.0" />-->
  <!--    </joint>-->
  <!-- end for simulation -->

  <mujoco>
    <compiler meshdir="/home/dzp/RoRL/roworld/envs/assets/mz25_sim/meshes/"
              balanceinertia="true"
              strippath="false"
              discardvisual="false"/>
  </mujoco>

  <link name="mz25_link0">
    <visual>
      <geometry>
        <mesh filename="visual/link0.stl"/>
      </geometry>
    </visual>
    <collision>
      <geometry>
        <mesh filename="collision/link0.stl"/>
      </geometry>
    </collision>
    <!-- for simulation -->
    <inertial>
      <origin rpy="0 0 0" xyz="0 0 0"/>
      <mass value="3.06"/>
      <inertia ixx="0.3" ixy="0.0" ixz="0.0" iyy="0.3" iyz="0.0" izz="0.3"/>
    </inertial>
    <!-- end for simulation -->
  </link>
  <link name="mz25_link1">
    <visual>
      <geometry>
        <mesh filename="visual/link1.stl"/>
      </geometry>
    </visual>
    <collision>
      <geometry>
        <mesh filename="collision/link1.stl"/>
      </geometry>
    </collision>
    <!-- for simulation -->
    <inertial>
      <origin rpy="0 0 0" xyz="0 0 0"/>
      <mass value="2.34"/>
      <inertia ixx="0.3" ixy="0.0" ixz="0.0" iyy="0.3" iyz="0.0" izz="0.3"/>
    </inertial>
    <!-- end for simulation -->
  </link>
  <joint name="mz25_joint1" type="revolute">
    <safety_controller k_position="100.0" k_velocity="40.0" soft_lower_limit="-2.97" soft_upper_limit="2.97"/>
    <origin rpy="0 0 0" xyz="0 0 0.2495"/>
    <parent link="mz25_link0"/>
    <child link="mz25_link1"/>
    <axis xyz="0 0 1"/>
    <limit effort="400" lower="-2.97" upper="2.97" velocity="3.67"/>
    <!-- for simulation -->
    <dynamics damping="1.0"/>
    <!-- end for simulation -->
  </joint>
  <link name="mz25_link2">
    <visual>
      <geometry>
        <mesh filename="visual/link2.stl"/>
      </geometry>
    </visual>
    <collision>
      <geometry>
        <mesh filename="collision/link2.stl"/>
      </geometry>
    </collision>
    <!-- for simulation -->
    <inertial>
      <origin rpy="0 0 0" xyz="0 0 0"/>
      <mass value="23.6"/>
      <inertia ixx="0.3" ixy="0.0" ixz="0.0" iyy="0.3" iyz="0.0" izz="0.3"/>
    </inertial>
    <!-- end for simulation -->
  </link>
  <joint name="mz25_joint2" type="revolute">
    <safety_controller k_position="100.0" k_velocity="40.0" soft_lower_limit="-2.62" soft_upper_limit="1.83"/>
    <origin rpy="0 0 -1.57079632679" xyz="0.17 0.157 0.3005"/>
    <parent link="mz25_link1"/>
    <child link="mz25_link2"/>
    <axis xyz="1 0 0"/>
    <limit effort="400" lower="-2.62" upper="1.83" velocity="3.23"/>
    <!-- for simulation -->
    <dynamics damping="1.0"/>
    <!-- end for simulation -->
  </joint>
  <link name="mz25_link3">
    <visual>
      <geometry>
        <mesh filename="visual/link3.stl"/>
      </geometry>
    </visual>
    <collision>
      <geometry>
        <mesh filename="collision/link3.stl"/>
      </geometry>
    </collision>
    <!-- for simulation -->
    <inertial>
      <origin rpy="0 0 0" xyz="0 0 0"/>
      <mass value="23.8"/>
      <inertia ixx="0.3" ixy="0.0" ixz="0.0" iyy="0.3" iyz="0.0" izz="0.3"/>
    </inertial>
    <!-- end for simulation -->
  </link>
  <joint name="mz25_joint3" type="revolute">
    <safety_controller k_position="100.0" k_velocity="40.0" soft_lower_limit="-1.43" soft_upper_limit="3.21"/>
    <origin rpy="0 0 1.57079632679" xyz="0.157 0 0.88"/>
    <parent link="mz25_link2"/>
    <child link="mz25_link3"/>
    <axis xyz="0 -1 0"/>
    <limit effort="400" lower="-1.43" upper="3.21" velocity="4.71"/>
    <!-- for simulation -->
    <dynamics damping="1.0"/>
    <!-- end for simulation -->
  </joint>
  <link name="mz25_link4">
    <visual>
      <geometry>
        <mesh filename="visual/link4.stl"/>
      </geometry>
    </visual>
    <collision>
      <geometry>
        <mesh filename="collision/link4.stl"/>
      </geometry>
    </collision>
    <!-- for simulation -->
    <inertial>
      <origin rpy="0 0 0" xyz="0 0 0"/>
      <mass value="24.3"/>
      <inertia ixx="0.3" ixy="0.0" ixz="0.0" iyy="0.3" iyz="0.0" izz="0.3"/>
    </inertial>
    <!-- end for simulation -->
  </link>
  <joint name="mz25_joint4" type="revolute">
    <safety_controller k_position="100.0" k_velocity="40.0" soft_lower_limit="-3.32" soft_upper_limit="3.32"/>
    <origin rpy="0 0 0" xyz="0.81 0 0.19"/>
    <parent link="mz25_link3"/>
    <child link="mz25_link4"/>
    <axis xyz="1 0 0"/>
    <limit effort="400" lower="-3.32" upper="3.32" velocity="7.33"/>
    <!-- for simulation -->
    <dynamics damping="1.0"/>
    <!-- end for simulation -->
  </joint>
  <link name="mz25_link5">
    <visual>
      <geometry>
        <mesh filename="visual/link5.stl"/>
      </geometry>
    </visual>
    <collision>
      <geometry>
        <mesh filename="collision/link5.stl"/>
      </geometry>
    </collision>
    <!-- for simulation -->
    <inertial>
      <origin rpy="0 0 0" xyz="0 0 0"/>
      <mass value="35"/>
      <inertia ixx="0.3" ixy="0.0" ixz="0.0" iyy="0.3" iyz="0.0" izz="0.3"/>
    </inertial>
    <!-- end for simulation -->
  </link>
  <joint name="mz25_joint5" type="revolute">
    <safety_controller k_position="100.0" k_velocity="40.0" soft_lower_limit="-2.53" soft_upper_limit="2.53"/>
    <origin rpy="0 0 0" xyz="0 0 0"/>
    <parent link="mz25_link4"/>
    <child link="mz25_link5"/>
    <axis xyz="0 -1 0"/>
    <limit effort="60" lower="-2.53" upper="2.53" velocity="7.33"/>
    <!-- for simulation -->
    <dynamics damping="1.0"/>
    <!-- end for simulation -->
  </joint>
  <link name="mz25_link6">
    <visual>
      <geometry>
        <mesh filename="visual/link6.stl"/>
      </geometry>
    </visual>
    <collision>
      <geometry>
        <mesh filename="collision/link6.stl"/>
      </geometry>
    </collision>
    <!-- for simulation -->
    <inertial>
      <origin rpy="0 0 0" xyz="0 0 0"/>
      <mass value="1.47"/>
      <inertia ixx="0.3" ixy="0.0" ixz="0.0" iyy="0.3" iyz="0.0" izz="0.3"/>
    </inertial>
    <!-- end for simulation -->
  </link>
  <joint name="mz25_joint6" type="revolute">
    <safety_controller k_position="100.0" k_velocity="40.0" soft_lower_limit="-6.28" soft_upper_limit="6.28"/>
    <origin rpy="0 0 0" xyz="0.101 0 0"/>
    <parent link="mz25_link5"/>
    <child link="mz25_link6"/>
    <axis xyz="1 0 0"/>
    <limit effort="12" lower="-6.28" upper="6.28" velocity="11.73"/>
    <!-- for simulation -->
    <dynamics damping="1.0"/>
    <!-- end for simulation -->
  </joint>
  <!--  <xacro:panda_gazebo robot_name="$(arg robot_name)" />-->
  <!--  <xacro:panda_transmission robot_name="$(arg robot_name)" load_hand="false" />-->
  <!-- end for simulation -->
</robot>

