<mujocoinclude>

    <body name="base_link" pos="0 0.4 0.9" quat="0.3826834324 0 0 0.9238795325" >
        <!-- The mass 4 kg of base link might be incorrect (it is for ur5) -->
        <inertial pos="0 0 0" quat="0.5 0.5 -0.5 0.5" mass="4" diaginertia="0.0072 0.00443333 0.00443333" />
        <geom mesh="C_base" class="D_robot_collision" />
        <geom mesh="V_base" class="D_robot_visual" />

        <body name="shoulder_link" pos="0 0 0.163">
            <inertial pos="0 0 0" mass="3.7" diaginertia="0.0102675 0.0102675 0.00666" />
            <geom mesh="C_shoulder" class="D_robot_collision" />
            <geom mesh="V_shoulder" class="D_robot_visual" />
            <joint name="shoulder_pan_joint" pos="0 0 0" axis="0 0 1" limited="true" range="-6.28319 6.28319" />

            <body name="upper_arm_link" pos="0 0.138 0" quat="0.707107 0 0.707107 0">
                <inertial pos="0 0 0.2125" mass="8.393" diaginertia="0.133886 0.133886 0.0151074" />
                <geom mesh="C_upperarm" class="D_robot_collision" />
                <geom mesh="V_upperarm" class="D_robot_visual" />
                <joint name="shoulder_lift_joint" pos="0 0 0" axis="0 1 0" limited="true" range="-6.28319 6.28319" />

                <body name="forearm_link" pos="0 -0.131 0.425">
                    <inertial pos="0 0 0.196" mass="2.275" diaginertia="0.0311796 0.0311796 0.004095" />
                    <geom mesh="C_forearm" class="D_robot_collision" />
                    <geom mesh="V_forearm" class="D_robot_visual" />
                    <joint name="elbow_joint" pos="0 0 0" axis="0 1 0" limited="true" range="-3.14159 3.14159" />

                    <body name="wrist_1_link" pos="0 0 0.392" quat="0.707107 0 0.707107 0">
                        <inertial pos="0 0 0" quat="0.5 0.5 -0.5 0.5" mass="1.219" diaginertia="0.21942 0.111173 0.111173" />
                        <geom mesh="C_wrist1" class="D_robot_collision" />
                        <geom mesh="V_wrist1" class="D_robot_visual" />
                        <joint name="wrist_1_joint" pos="0 0 0" axis="0 1 0" limited="true" range="-6.28319 6.28319" />

                        <body name="wrist_2_link" pos="0 0.127 0">
                            <inertial pos="0 0 0.1" mass="1.219" diaginertia="0.0025599 0.0025599 0.0021942" />
                            <geom mesh="C_wrist2" class="D_robot_collision" />
                            <geom mesh="V_wrist2" class="D_robot_visual" />
                            <joint name="wrist_2_joint" pos="0 0 0" axis="0 0 1" limited="true" range="-6.28319 6.28319" />

                            <body name="wrist_3_link" pos="0 0 0.1">
                                <inertial pos="0 0.0771683 0" quat="0.707107 0 0 0.707107" mass="0.1889" diaginertia="0.000132134 9.90863e-05 9.90863e-05" />
                                <geom mesh="C_wrist3" class="D_robot_collision" />
                                <geom mesh="V_wrist3" class="D_robot_visual" />
                                <joint name="wrist_3_joint" pos="0 0 0" axis="0 1 0" limited="true" range="-6.28319 6.28319" />

                                <body name="ee_link" pos="0 0.0823 0" quat="0.707107 -0.707107 0 0">
                                    <inertial pos="0 0.0823 0" quat="0.707107 -0.707107 0 0" mass="0" diaginertia="0 0 0" />

                                    <!--camera name="gripper_camera" euler="0 3.14159265 0" fovy="63.5" /-->
                                    <geom name="light_1" type="sphere" size="0.005" pos="0.035 0 0.0166" material="M_light" />
                                    <geom name="light_2" type="sphere" size="0.005" pos="-0.035 0 0.0166" material="M_light" />
                                    <geom name="kinova_robotiq_coupler_mesh" type="mesh" mesh="kinova_robotiq_coupler" pos="0 0 0.0466" material="M_gripper" />
                                    <geom name="robotiq_85_base_link_mesh" type="mesh" mesh="robotiq_85_base_link" pos="0 0 0.0016" quat="0.707107 0 -0.707107 0" material="M_gripper" />

                                    <body name="right_driver" pos="0 -0.0306011 0.054904" quat="0.707107 0 -0.707107 0">
                                        <geom name="right_driver_mesh" type="mesh" mesh="robotiq_85_knuckle_link" material="M_gripper" contype="0" conaffinity="0" />
                                        <joint name="joint7_1" axis="0 0 1" type="hinge" limited="true" range="0 0.872664626" />

                                        <body name="right_coupler" pos="0 -0.0315 0">
                                            <geom name="right_coupler_mesh" type="mesh" mesh="robotiq_85_finger_link" material="M_gripper" contype="0" conaffinity="0" />
                                            <joint name="joint8_1" axis="0 0 1" type="hinge" limited="true" range="0 2.967059728" />

                                            <body name="right_follower_link" pos="0.0475 -0.006 0">
                                                <geom name="right_follower_mesh" pos="0.0025 0.021 0" type="mesh" mesh="robotiq_85_finger_tip_link" material="M_gripper" />
                                                <joint name="joint9_1" axis="0 0 1" type="hinge" limited="true" range="0 2.967059728" />
                                            </body>
                                        </body>
                                    </body>

                                    <body name="right_spring_link" pos="0.0016 -0.012 0.0614" quat="0.707107 0 -0.707107 0">
                                        <geom name="right_spring_mesh" type="mesh" pos="0 -0.0005 0.0016" mesh="robotiq_85_inner_knuckle_link" material="M_gripper" contype="0" conaffinity="0" />
                                        <joint name="joint10_1" axis="0 0 1" type="hinge" limited="true" range="0 1" />
                                    </body>

                                    <body name="left_driver" pos="0 0.0306011 0.054904" quat="0 0.707107 0 0.707107">
                                        <geom name="left_driver_mesh" type="mesh" mesh="robotiq_85_knuckle_link" material="M_gripper" contype="0" conaffinity="0" />
                                        <joint name="joint7_2" axis="0 0 1" type="hinge" limited="true" range="0 0.872664626" />

                                        <body name="left_coupler" pos="0 -0.0315 0">
                                            <geom name="left_coupler_mesh" type="mesh" mesh="robotiq_85_finger_link" material="M_gripper" contype="0" conaffinity="0" />
                                            <joint name="joint8_2" axis="0 0 1" type="hinge" limited="true" range="0 2.967059728" />

                                            <body name="left_follower_link" pos="0.0475 -0.006 0">
                                                <geom name="left_follower_mesh" pos="0.0025 0.021 0" type="mesh" mesh="robotiq_85_finger_tip_link" material="M_gripper" />
                                                <joint name="joint9_2" axis="0 0 1" type="hinge" limited="true" range="0 2.967059728" />
                                            </body>
                                        </body>

                                    </body>

                                    <body name="left_spring_link" pos="0.0016 0.012 0.0614" quat="0 0.707107 0 0.707107">
                                        <geom name="left_spring_mesh" type="mesh" pos="0 0.0005 0.0016" mesh="robotiq_85_inner_knuckle_link" material="M_gripper" contype="0" conaffinity="0" />
                                        <joint name="joint10_2" axis="0 0 1" type="hinge" limited="true" range="0 1" />
                                    </body>

                                </body>
                            </body>
                        </body>
                    </body>
                </body>
            </body>
        </body>
    </body>

</mujocoinclude>